<?xml version="1.0" ?>
<!-- =================================================================================== -->
<!-- |    This document was autogenerated by xacro from /home/fra/mifood_ws/src/justin/HarvestingRobot/src/lrwr_description/urdf/nova5_robot_panther_camera.xacro | -->
<!-- |    EDITING THIS FILE BY HAND IS NOT RECOMMENDED                                 | -->
<!-- =================================================================================== -->
<robot name="nova5_robot">
    <gazebo reference="camera_bottom_screw_frame">
        <sensor name="wrist_camera" type="depth">
            <!-- openni plugin has the x pointing towards the scene, so rotate to have z -->
            <update_rate>20</update_rate>
            <camera>
                <horizontal_fov>1.047198</horizontal_fov>
                <image>
                    <width>640</width>
                    <height>480</height>
                    <format>R8G8B8</format>
                </image>
                <clip>
                    <near>0.05</near>
                    <far>10</far>
                </clip>
            </camera>
            <plugin filename="libgazebo_ros_openni_kinect.so" name="camera_plugin">
                <baseline>0.2</baseline>
                <alwaysOn>true</alwaysOn>
                <visualize>true</visualize>
                <!-- Keep this zero, update_rate in the parent <sensor> tag
                will control the frame rate. -->
                <updateRate>0.0</updateRate>
                <cameraName>camera_ir</cameraName>
                <imageTopicName>/camera/color/image_raw</imageTopicName>
                <cameraInfoTopicName>/camera/color/camera_info</cameraInfoTopicName>
                <depthImageTopicName>/camera/depth/image_raw</depthImageTopicName>
                <depthImageCameraInfoTopicName>/camera/depth/camera_info</depthImageCameraInfoTopicName>
                <pointCloudTopicName>/camera/depth/points</pointCloudTopicName>
                <frameName>camera_bottom_screw_frame</frameName>
                <pointCloudCutoff>0.5</pointCloudCutoff>
                <pointCloudCutoffMax>3.0</pointCloudCutoffMax>
                <distortionK1>0</distortionK1>
                <distortionK2>0</distortionK2>
                <distortionK3>0</distortionK3>
                <distortionT1>0</distortionT1>
                <distortionT2>0</distortionT2>
                <CxPrime>0</CxPrime>
                <Cx>0</Cx>
                <Cy>0</Cy>
                <focalLength>0</focalLength>
                <hackBaseline>0</hackBaseline>
            </plugin>
        </sensor>
        <plugin name="gazebo_ros_control" filename="libgazebo_ros_control.so">
            <robotNamespace>/</robotNamespace>
        </plugin>
    </gazebo>
    <!-- PLATFORM TYPES
   panther
   hunter
   -->
    <link name="world" />
    <joint name="world_joint" type="fixed">
        <origin rpy="0 0 0" xyz="0 0 0.16" />
        <parent link="world" />
        <child link="mobile_platform_link" />
    </joint>
    <material name="aluminum">
        <color rgba="0.5 0.5 0.5 1" />
    </material>
    <material name="plastic">
        <color rgba="0.1 0.1 0.1 1" />
    </material>
    <!-- <link name="cylinder_link">
    <visual>
      <origin xyz="0 0 0.04" rpy="0 0 0"/>
      <geometry>
        <cylinder length="${h}" radius="${r}"/>
      </geometry>
      <material name="green">
        <color rgba="0 1 0 1"/>
      </material>
    </visual>
    <inertial>
      <origin xyz="0 0 0.04" rpy="0 0 0"/>
      <mass value="0.01"/>
      <inertia ixx="0.00308109148952278"
        ixy="-4.0369958400766E-08"
        ixz="5.2607663395944E-07"
        iyy="0.00309758743296662"
        iyz="-6.37484696538659E-09"
        izz="0.00232835367593981" />
    </inertial>
    <collision>
      <origin xyz="0 0 0.04" rpy="0 0 0"/>
      <geometry>
        <cylinder length="${h}" radius="${r}"/>
      </geometry>
    </collision>
  </link>
  <gazebo reference="cylinder_link">
    <material>Gazebo/Black</material>
    <dampingFactor>0.05</dampingFactor>
    <kp>1000000</kp>
    <kd>1.0</kd>
    <mu1>100.0</mu1>
    <mu2>100.0</mu2>
    <minDepth>0.001</minDepth>
  </gazebo> -->
    <!-- <joint
    name="robot_joint"
    type="fixed">
    <origin
      xyz="0 0 0.15"
      rpy="0 0 0" />
    <parent
      link="cylinder_link" />
    <child
      link="base_link" />
  </joint> -->
    <link name="mobile_platform_link">
        <visual>
            <origin rpy="0 0 0" xyz="0 0 0" />
            <geometry>
                <mesh filename="package://dobot_description/meshes/nova5/panther.stl" scale="0.001 0.001 0.001" />
            </geometry>
        </visual>
        <inertial>
            <origin rpy="0 0 0" xyz="0 0 0.04" />
            <mass value="0.01" />
            <inertia ixx="0.00308109148952278" ixy="-4.0369958400766E-08" ixz="5.2607663395944E-07" iyy="0.00309758743296662" iyz="-6.37484696538659E-09" izz="0.00232835367593981" />
        </inertial>
        <collision>
            <origin rpy="0 0 0" xyz="0 0 0" />
            <geometry>
                <box size="0.1 0.1 0.1" />
            </geometry>
        </collision>
    </link>
    <gazebo reference="mobile_platform_link">
        <material>Gazebo/Grey</material>
        <dampingFactor>0.05</dampingFactor>
        <kp>1000000</kp>
        <kd>1.0</kd>
        <mu1>100.0</mu1>
        <mu2>100.0</mu2>
        <minDepth>0.001</minDepth>
    </gazebo>
    <joint name="robot_joint" type="fixed">
        <origin rpy="0 0 0" xyz="0 0 0.13" />
        <parent link="mobile_platform_link" />
        <child link="base_link" />
    </joint>
    <link name="base_link">
        <inertial>
            <origin rpy="0 0 0" xyz="6.56698714338847E-06 2.73052159273858E-06 0.0698223124889706" />
            <mass value="1.3106443915978" />
            <inertia ixx="0.00308109148952278" ixy="-4.0369958400766E-08" ixz="5.2607663395944E-07" iyy="0.00309758743296662" iyz="-6.37484696538659E-09" izz="0.00232835367593981" />
        </inertial>
        <visual>
            <origin rpy="0 0 0" xyz="0 0 0" />
            <geometry>
                <mesh filename="package://dobot_description/meshes/nova5/base_link.STL" />
            </geometry>
            <material name="">
                <color rgba="0.792156862745098 0.819607843137255 0.933333333333333 1" />
            </material>
        </visual>
        <collision>
            <origin rpy="0 0 0" xyz="0 0 0" />
            <geometry>
                <mesh filename="package://dobot_description/meshes/nova5/base_link.STL" />
            </geometry>
        </collision>
    </link>
    <link name="Link1">
        <inertial>
            <origin rpy="0 0 0" xyz="9.18642704220017E-06 -0.021770784235076 -0.0261833991373472" />
            <mass value="1.08090940330212" />
            <inertia ixx="0.00265963193119309" ixy="1.85196348994647E-07" ixz="-3.27720040926316E-07" iyy="0.00247342331575097" iyz="0.000661331129337329" izz="0.00164737186015792" />
        </inertial>
        <visual>
            <origin rpy="0 0 0" xyz="0 0 0" />
            <geometry>
                <mesh filename="package://dobot_description/meshes/nova5/Link1.STL" />
            </geometry>
            <material name="">
                <color rgba="0.792156862745098 0.819607843137255 0.933333333333333 1" />
            </material>
        </visual>
        <collision>
            <origin rpy="0 0 0" xyz="0 0 0" />
            <geometry>
                <mesh filename="package://dobot_description/meshes/nova5/Link1.STL" />
            </geometry>
        </collision>
    </link>
    <joint name="joint1" type="revolute">
        <origin rpy="0 0 0" xyz="0 0 0.240000000000178" />
        <parent link="base_link" />
        <child link="Link1" />
        <axis xyz="0 0 1" />
        <limit effort="40000" lower="-6.28" upper="6.28" velocity="40000" />
    </joint>
    <link name="Link2">
        <inertial>
            <origin rpy="0 0 0" xyz="-0.19933810729628 -0.00696463483971123 0.109208661556353" />
            <mass value="2.54585370113969" />
            <inertia ixx="0.00285193319464959" ixy="-0.00212784400881843" ixz="-0.00109906472415148" iyy="0.0636767872390402" iyz="-3.83872488712299E-05" izz="0.0643005121111712" />
        </inertial>
        <visual>
            <origin rpy="0 0 0" xyz="0 0 0" />
            <geometry>
                <mesh filename="package://dobot_description/meshes/nova5/Link2.STL" />
            </geometry>
            <material name="">
                <color rgba="0.792156862745098 0.819607843137255 0.933333333333333 1" />
            </material>
        </visual>
        <collision>
            <origin rpy="0 0 0" xyz="0 0 0" />
            <geometry>
                <mesh filename="package://dobot_description/meshes/nova5/Link2.STL" />
            </geometry>
        </collision>
    </link>
    <joint name="joint2" type="revolute">
        <origin rpy="-1.57080287682252 1.53586622836832 3.14159265358979" xyz="0 0 0" />
        <parent link="Link1" />
        <child link="Link2" />
        <axis xyz="0 0 1" />
        <limit effort="40000" lower="-3.14" upper="3.14" velocity="40000" />
    </joint>
    <link name="Link3">
        <inertial>
            <origin rpy="0 0 0" xyz="-0.152357289724291 -0.0053571688729055 0.0198991511385547" />
            <mass value="1.40745649848125" />
            <inertia ixx="0.00100801309674517" ixy="-0.00077546601599374" ixz="4.43267247578911E-05" iyy="0.0231741793950995" iyz="1.31338010910521E-06" izz="0.02359962285525" />
        </inertial>
        <visual>
            <origin rpy="0 0 0" xyz="0 0 0" />
            <geometry>
                <mesh filename="package://dobot_description/meshes/nova5/Link3.STL" />
            </geometry>
            <material name="">
                <color rgba="0.792156862745098 0.819607843137255 0.933333333333333 1" />
            </material>
        </visual>
        <collision>
            <origin rpy="0 0 0" xyz="0 0 0" />
            <geometry>
                <mesh filename="package://dobot_description/meshes/nova5/Link3.STL" />
            </geometry>
        </collision>
    </link>
    <joint name="joint3" type="revolute">
        <origin rpy="0 0 0" xyz="-0.399756009268664 -0.0139690033141953 0" />
        <parent link="Link2" />
        <child link="Link3" />
        <axis xyz="0 0 1" />
        <limit effort="40000" lower="-2.79" upper="2.79" velocity="40000" />
    </joint>
    <link name="Link4">
        <inertial>
            <origin rpy="0 0 0" xyz="-6.37112093033953E-06 -0.0227590499933018 -0.0202381689250349" />
            <mass value="0.439666284541787" />
            <inertia ixx="0.000634738696193051" ixy="1.33529119545257E-08" ixz="2.91412587537874E-08" iyy="0.00045014395177395" iyz="0.000210919680187578" izz="0.000480311391216564" />
        </inertial>
        <visual>
            <origin rpy="0 0 0" xyz="0 0 0" />
            <geometry>
                <mesh filename="package://dobot_description/meshes/nova5/Link4.STL" />
            </geometry>
            <material name="">
                <color rgba="0.792156862745098 0.819607843137255 0.933333333333333 1" />
            </material>
        </visual>
        <collision>
            <origin rpy="0 0 0" xyz="0 0 0" />
            <geometry>
                <mesh filename="package://dobot_description/meshes/nova5/Link4.STL" />
            </geometry>
        </collision>
    </link>
    <joint name="joint4" type="revolute">
        <origin rpy="0 0 -1.53586622840712" xyz="-0.329798707647103 -0.0115244277211674 0.134999532858734" />
        <parent link="Link3" />
        <child link="Link4" />
        <axis xyz="0 0 1" />
        <limit effort="40000" lower="-6.28" upper="6.28" velocity="40000" />
    </joint>
    <link name="Link5">
        <inertial>
            <origin rpy="0 0 0" xyz="-1.27925890990664E-06 0.00190911597991161 -0.0076111865696753" />
            <mass value="0.574835130260071" />
            <inertia ixx="0.000663176880523558" ixy="1.30179448329138E-08" ixz="1.22670358756949E-08" iyy="0.000397520749670404" iyz="-0.00012026389265228" izz="0.000641156648195347" />
        </inertial>
        <visual>
            <origin rpy="0 0 0" xyz="0 0 0" />
            <geometry>
                <mesh filename="package://dobot_description/meshes/nova5/Link5.STL" />
            </geometry>
            <material name="">
                <color rgba="0.792156862745098 0.819607843137255 0.933333333333333 1" />
            </material>
        </visual>
        <collision>
            <origin rpy="0 0 0" xyz="0 0 0" />
            <geometry>
                <mesh filename="package://dobot_description/meshes/nova5/Link5.STL" />
            </geometry>
        </collision>
    </link>
    <joint name="joint5" type="revolute">
        <origin rpy="1.5708 0 0" xyz="0 -0.12 0" />
        <parent link="Link4" />
        <child link="Link5" />
        <axis xyz="0 0 1" />
        <limit effort="40000" lower="-6.28" upper="6.28" velocity="40000" />
    </joint>
    <link name="Link6">
        <inertial>
            <origin rpy="0 0 0" xyz="1.5476173180832E-06 0.000151598525687691 -0.0194592287865595" />
            <mass value="0.129679940383395" />
            <inertia ixx="5.02803124561327E-05" ixy="6.27222112028976E-11" ixz="3.5128727780266E-12" iyy="5.05400746124736E-05" iyz="5.0343678900728E-08" izz="7.7863015024978E-05" />
        </inertial>
        <visual>
            <origin rpy="0 0 0" xyz="0 0 0" />
            <geometry>
                <mesh filename="package://dobot_description/meshes/nova5/Link6.STL" />
            </geometry>
            <material name="">
                <color rgba="0.752941176470588 0.752941176470588 0.752941176470588 1" />
            </material>
        </visual>
        <collision>
            <origin rpy="0 0 0" xyz="0 0 0" />
            <geometry>
                <mesh filename="package://dobot_description/meshes/nova5/Link6.STL" />
            </geometry>
        </collision>
    </link>
    <joint name="joint6" type="revolute">
        <origin rpy="-1.5708 0 0" xyz="0 0.088328 0" />
        <parent link="Link5" />
        <child link="Link6" />
        <axis xyz="0 0 1" />
        <limit effort="40000" lower="-6.28" upper="6.28" velocity="40000" />
    </joint>
    <link name="base_link_gripper">
        <inertial>
            <origin rpy="0 0 0" xyz="-3.9257E-06 -0.00027208 0.037806" />
            <mass value="0.34365" />
            <inertia ixx="0.00036805" ixy="-7.2868E-08" ixz="-5.0168E-08" iyy="0.0003341" iyz="-2.6462E-06" izz="0.00022294" />
        </inertial>
        <visual>
            <origin rpy="0 0 0" xyz="0 0 0" />
            <geometry>
                <mesh filename="package://dh_pgc140_urdf/meshes/base_link.STL" />
            </geometry>
            <material name="">
                <color rgba="1 1 1 1" />
            </material>
        </visual>
        <collision>
            <origin rpy="0 0 0" xyz="0 0 0" />
            <geometry>
                <mesh filename="package://dh_pgc140_urdf/meshes/base_link.STL" />
            </geometry>
        </collision>
    </link>
    <link name="camera_bottom_screw_frame" />
    <!-- <joint name="camera_joint" type="fixed">
      <origin rpy="0 -1.57 0" xyz="0.065 0 0" />
      <parent link="base_link_gripper" />
      <child link="camera_bottom_screw_frame" />
  </joint> -->
    <joint name="camera_joint" type="fixed">
        <origin rpy="0 0 -1.57" xyz="0 -0.360 0.02" />
        <parent link="base_link" />
        <child link="camera_bottom_screw_frame" />
    </joint>
    <link name="camera_link">
        <visual>
            <!-- the mesh origin is at front plate in between the two infrared camera axes -->
            <!-- <origin xyz="${d455_zero_depth_to_glass-d455_cam_depth/2} ${-d455_cam_depth_py} 0" rpy="0 0 0"/> -->
            <origin rpy="1.5707963267948966 0 1.5707963267948966" xyz="0.00465 0 0" />
            <geometry>
                <!-- <box size="${d455_cam_depth} ${d455_cam_width} ${d455_cam_height}"/> -->
                <mesh filename="package://realsense2_description/meshes/d435.stl" scale="0.001 0.001 0.001" />
            </geometry>
            <material name="aluminum" />
        </visual>
        <collision>
            <origin rpy="0 0 0" xyz="-0.00845 -0.0475 0" />
            <geometry>
                <box size="0.026 0.124 0.029" />
            </geometry>
        </collision>
        <inertial>
            <!-- The following are not reliable values, and should not be used for modeling -->
            <mass value="0.072" />
            <origin rpy="0 0 0" xyz="0 0 0" />
            <inertia ixx="0.003881243" ixy="0.0" ixz="0.0" iyy="0.000498940" iyz="0.0" izz="0.003879257" />
        </inertial>
    </link>
    <!-- Change camera position-->
    <!-- <joint name="camera_link_joint" type="fixed">
    <origin rpy="0 0 0" xyz="${camera_position}" />
    <parent link="camera_bottom_screw_frame" />
    <child link="camera_link" />
  </joint> -->
    <!-- <xacro:sensor_d435 name="camera" topics_ns="camera" parent="base_link_gripper" publish_pointcloud="true">
    <origin xyz="0 0 0" rpy="0 0 0" />
  </xacro:sensor_d435>   -->
    <joint name="camera_link_joint" type="fixed">
        <origin rpy="0 0 0" xyz="0.011150000000000002 0 0.0145" />
        <parent link="camera_bottom_screw_frame" />
        <child link="camera_link" />
    </joint>
    <material name="camera_aluminum">
        <color rgba="0.5 0.5 0.5 1" />
    </material>
    <!-- camera depth joints and links -->
    <joint name="camera_depth_joint" type="fixed">
        <origin rpy="0 0 0" xyz="0 0 0" />
        <parent link="camera_link" />
        <child link="camera_depth_frame" />
    </joint>
    <link name="camera_depth_frame" />
    <joint name="camera_depth_optical_joint" type="fixed">
        <origin rpy="-1.5707963267948966 0 -1.5707963267948966" xyz="0 0 0" />
        <parent link="camera_depth_frame" />
        <child link="camera_depth_optical_frame" />
    </joint>
    <link name="camera_depth_optical_frame" />
    <!-- camera left IR joints and links -->
    <joint name="camera_left_ir_joint" type="fixed">
        <origin rpy="0 0 0" xyz="0 0.0 0" />
        <parent link="camera_depth_frame" />
        <child link="camera_left_ir_frame" />
    </joint>
    <link name="camera_left_ir_frame" />
    <joint name="camera_left_ir_optical_joint" type="fixed">
        <origin rpy="-1.5707963267948966 0 -1.5707963267948966" xyz="0 0 0" />
        <parent link="camera_left_ir_frame" />
        <child link="camera_left_ir_optical_frame" />
    </joint>
    <link name="camera_left_ir_optical_frame" />
    <!-- camera right IR joints and links -->
    <joint name="camera_right_ir_joint" type="fixed">
        <origin rpy="0 0 0" xyz="0 -0.05 0" />
        <parent link="camera_depth_frame" />
        <child link="camera_right_ir_frame" />
    </joint>
    <link name="camera_right_ir_frame" />
    <joint name="camera_right_ir_optical_joint" type="fixed">
        <origin rpy="-1.5707963267948966 0 -1.5707963267948966" xyz="0 0 0" />
        <parent link="camera_right_ir_frame" />
        <child link="camera_right_ir_optical_frame" />
    </joint>
    <link name="camera_right_ir_optical_frame" />
    <!-- camera color joints and links -->
    <joint name="camera_color_joint" type="fixed">
        <origin rpy="0 0 0" xyz="0 0.015 0" />
        <parent link="camera_depth_frame" />
        <child link="camera_color_frame" />
    </joint>
    <link name="camera_color_frame" />
    <joint name="camera_color_optical_joint" type="fixed">
        <origin rpy="-1.5707963267948966 0 -1.5707963267948966" xyz="0 0 0" />
        <parent link="camera_color_frame" />
        <child link="camera_color_optical_frame" />
    </joint>
    <link name="camera_color_optical_frame" />
    <gazebo reference="camera_link">
        <self_collide>0</self_collide>
        <enable_wind>0</enable_wind>
        <kinematic>0</kinematic>
        <gravity>1</gravity>
        <!--<mu>1</mu>-->
        <mu2>1</mu2>
        <fdir1>0 0 0</fdir1>
        <!--<slip1>0</slip1>
      <slip2>0</slip2>-->
        <kp>1e+13</kp>
        <kd>1</kd>
        <!--<max_vel>0.01</max_vel>
      <min_depth>0</min_depth>-->
        <sensor name="cameracolor" type="camera">
            <camera name="camera">
                <horizontal_fov>1.2112585008840648</horizontal_fov>
                <image>
                    <width>640</width>
                    <height>480</height>
                    <format>RGB_INT8</format>
                </image>
                <clip>
                    <near>0.1</near>
                    <far>100</far>
                </clip>
                <noise>
                    <type>gaussian</type>
                    <mean>0.0</mean>
                    <stddev>0.007</stddev>
                </noise>
            </camera>
            <always_on>1</always_on>
            <update_rate>30</update_rate>
            <visualize>1</visualize>
        </sensor>
        <sensor name="cameraired1" type="camera">
            <camera name="camera">
                <horizontal_fov>1.4870205226991688</horizontal_fov>
                <image>
                    <width>1280</width>
                    <height>720</height>
                    <format>L_INT8</format>
                </image>
                <clip>
                    <near>0.1</near>
                    <far>100</far>
                </clip>
                <noise>
                    <type>gaussian</type>
                    <mean>0.0</mean>
                    <stddev>0.05</stddev>
                </noise>
            </camera>
            <always_on>1</always_on>
            <update_rate>90</update_rate>
            <visualize>0</visualize>
        </sensor>
        <sensor name="cameraired2" type="camera">
            <camera name="camera">
                <horizontal_fov>1.4870205226991688</horizontal_fov>
                <image>
                    <width>1280</width>
                    <height>720</height>
                    <format>L_INT8</format>
                </image>
                <clip>
                    <near>0.1</near>
                    <far>100</far>
                </clip>
                <noise>
                    <type>gaussian</type>
                    <mean>0.0</mean>
                    <stddev>0.05</stddev>
                </noise>
            </camera>
            <always_on>1</always_on>
            <update_rate>90</update_rate>
            <visualize>0</visualize>
        </sensor>
        <sensor name="cameradepth" type="depth">
            <camera name="camera">
                <horizontal_fov>1.4870205226991688</horizontal_fov>
                <image>
                    <width>1280</width>
                    <height>720</height>
                </image>
                <clip>
                    <near>0.1</near>
                    <far>100</far>
                </clip>
                <noise>
                    <type>gaussian</type>
                    <mean>0.0</mean>
                    <stddev>0.100</stddev>
                </noise>
            </camera>
            <always_on>1</always_on>
            <update_rate>90</update_rate>
            <visualize>0</visualize>
        </sensor>
    </gazebo>
    <gazebo>
        <plugin filename="librealsense_gazebo_plugin.so" name="camera">
            <prefix>camera</prefix>
            <depthUpdateRate>30.0</depthUpdateRate>
            <colorUpdateRate>30.0</colorUpdateRate>
            <infraredUpdateRate>30.0</infraredUpdateRate>
            <depthTopicName>depth/image_raw</depthTopicName>
            <depthCameraInfoTopicName>depth/camera_info</depthCameraInfoTopicName>
            <colorTopicName>color/image_raw</colorTopicName>
            <colorCameraInfoTopicName>color/camera_info</colorCameraInfoTopicName>
            <infrared1TopicName>infra1/image_raw</infrared1TopicName>
            <infrared1CameraInfoTopicName>infra1/camera_info</infrared1CameraInfoTopicName>
            <infrared2TopicName>infra2/image_raw</infrared2TopicName>
            <infrared2CameraInfoTopicName>infra2/camera_info</infrared2CameraInfoTopicName>
            <colorOpticalframeName>camera_color_optical_frame</colorOpticalframeName>
            <depthOpticalframeName>camera_depth_optical_frame</depthOpticalframeName>
            <infrared1OpticalframeName>camera_left_ir_optical_frame</infrared1OpticalframeName>
            <infrared2OpticalframeName>camera_right_ir_optical_frame</infrared2OpticalframeName>
            <rangeMinDepth>0.2</rangeMinDepth>
            <rangeMaxDepth>10.0</rangeMaxDepth>
            <pointCloud>True</pointCloud>
            <pointCloudTopicName>depth/color/points</pointCloudTopicName>
            <pointCloudCutoff>0.25</pointCloudCutoff>
            <pointCloudCutoffMax>9.0</pointCloudCutoffMax>
        </plugin>
    </gazebo>
    <link name="finger1_link">
        <inertial>
            <origin rpy="0 0 0" xyz="0.0030491 -0.0066024 0.0064209" />
            <mass value="0.014278" />
            <inertia ixx="1.7567E-06" ixy="-5.7832E-08" ixz="2.6803E-08" iyy="2.3034E-06" iyz="2.2145E-07" izz="1.3354E-06" />
        </inertial>
        <visual>
            <origin rpy="0 0 0" xyz="0 0 0" />
            <geometry>
                <mesh filename="package://dh_pgc140_urdf/meshes/finger1_Link.STL" />
            </geometry>
            <material name="">
                <color rgba="1 1 1 1" />
            </material>
        </visual>
        <collision>
            <origin rpy="0 0 0" xyz="0 0 0" />
            <geometry>
                <mesh filename="package://dh_pgc140_urdf/meshes/finger1_Link.STL" />
            </geometry>
        </collision>
    </link>
    <joint name="finger1_joint" type="prismatic">
        <origin rpy="0 0 -1.5708" xyz="0.0132 0.0265 0.093" />
        <parent link="base_link_gripper" />
        <child link="finger1_link" />
        <axis xyz="1 0 0" />
        <limit effort="40000" lower="-0.09" upper="0.025" velocity="40000" />
        <dynamics damping="0" friction="0" />
    </joint>
    <link name="finger2_link">
        <inertial>
            <origin rpy="0 0 0" xyz="0.0030491 -0.0066024 0.0064209" />
            <mass value="0.014278" />
            <inertia ixx="1.7567E-06" ixy="-5.7832E-08" ixz="2.6803E-08" iyy="2.3034E-06" iyz="2.2145E-07" izz="1.3354E-06" />
        </inertial>
        <visual>
            <origin rpy="0 0 0" xyz="0 0 0" />
            <geometry>
                <mesh filename="package://dh_pgc140_urdf/meshes/finger2_Link.STL" />
            </geometry>
            <material name="">
                <color rgba="0.79216 0.81961 0.93333 1" />
            </material>
        </visual>
        <collision>
            <origin rpy="0 0 0" xyz="0 0 0" />
            <geometry>
                <mesh filename="package://dh_pgc140_urdf/meshes/finger2_Link.STL" />
            </geometry>
        </collision>
    </link>
    <joint name="finger2_joint" type="prismatic">
        <origin rpy="0 0 1.5708" xyz="-0.0132 -0.0265 0.093" />
        <parent link="base_link_gripper" />
        <child link="finger2_link" />
        <axis xyz="1 0 0" />
        <limit effort="40000" lower="-0.09" upper="0.025" velocity="40000" />
        <mimic joint="finger1_joint" multiplier="1" offset="0" />
        <dynamics damping="0" friction="0" />
    </joint>
    <joint name="gripper_joint" type="fixed">
        <parent link="Link6" />
        <child link="base_link_gripper" />
        <origin rpy="0 0 0" xyz="0.0 0.0 0.0" />
    </joint>
    <transmission name="joint1_trans">
        <type>transmission_interface/SimpleTransmission</type>
        <joint name="joint1">
            <hardwareInterface>hardware_interface/PositionJointInterface</hardwareInterface>
        </joint>
        <actuator name="joint1_motor">
            <mechanicalReduction>1</mechanicalReduction>
            <hardwareInterface>hardware_interface/EffortJointInterface</hardwareInterface>
        </actuator>
    </transmission>
    <transmission name="joint2_trans">
        <type>transmission_interface/SimpleTransmission</type>
        <joint name="joint2">
            <hardwareInterface>hardware_interface/PositionJointInterface</hardwareInterface>
        </joint>
        <actuator name="joint2_motor">
            <mechanicalReduction>1</mechanicalReduction>
            <hardwareInterface>hardware_interface/EffortJointInterface</hardwareInterface>
        </actuator>
    </transmission>
    <transmission name="joint3_trans">
        <type>transmission_interface/SimpleTransmission</type>
        <joint name="joint3">
            <hardwareInterface>hardware_interface/PositionJointInterface</hardwareInterface>
        </joint>
        <actuator name="joint3_motor">
            <mechanicalReduction>1</mechanicalReduction>
            <hardwareInterface>hardware_interface/EffortJointInterface</hardwareInterface>
        </actuator>
    </transmission>
    <transmission name="joint4_trans">
        <type>transmission_interface/SimpleTransmission</type>
        <joint name="joint4">
            <hardwareInterface>hardware_interface/PositionJointInterface</hardwareInterface>
        </joint>
        <actuator name="joint4_motor">
            <mechanicalReduction>1</mechanicalReduction>
            <hardwareInterface>hardware_interface/EffortJointInterface</hardwareInterface>
        </actuator>
    </transmission>
    <transmission name="joint5_trans">
        <type>transmission_interface/SimpleTransmission</type>
        <joint name="joint5">
            <hardwareInterface>hardware_interface/PositionJointInterface</hardwareInterface>
        </joint>
        <actuator name="joint5_motor">
            <mechanicalReduction>1</mechanicalReduction>
            <hardwareInterface>hardware_interface/EffortJointInterface</hardwareInterface>
        </actuator>
    </transmission>
    <transmission name="joint6_trans">
        <type>transmission_interface/SimpleTransmission</type>
        <joint name="joint6">
            <hardwareInterface>hardware_interface/PositionJointInterface</hardwareInterface>
        </joint>
        <actuator name="joint6_motor">
            <mechanicalReduction>1</mechanicalReduction>
            <hardwareInterface>hardware_interface/EffortJointInterface</hardwareInterface>
        </actuator>
    </transmission>
    <transmission name="finger1_joint_trans">
        <type>transmission_interface/SimpleTransmission</type>
        <joint name="finger1_joint">
            <hardwareInterface>hardware_interface/PositionJointInterface</hardwareInterface>
        </joint>
        <actuator name="finger1_joint_motor">
            <mechanicalReduction>1</mechanicalReduction>
            <hardwareInterface>hardware_interface/EffortJointInterface</hardwareInterface>
        </actuator>
    </transmission>
    <transmission name="finger2_joint_trans">
        <type>transmission_interface/SimpleTransmission</type>
        <joint name="finger2_joint">
            <hardwareInterface>hardware_interface/PositionJointInterface</hardwareInterface>
        </joint>
        <actuator name="finger2_joint_motor">
            <mechanicalReduction>1</mechanicalReduction>
            <hardwareInterface>hardware_interface/EffortJointInterface</hardwareInterface>
        </actuator>
    </transmission>
    <gazebo>
        <plugin filename="libgazebo_ros_control.so" name="gazebo_ros_control">
            <robotNamespace>/nova5_robot</robotNamespace>
        </plugin>
    </gazebo>
    <gazebo>
        <plugin filename="libgazebo_grasp_fix.so" name="gazebo_grasp_fix">
            <arm>
                <arm_name>nova5_robot</arm_name>
                <palm_link>Link6</palm_link>
                <gripper_link>finger1_link</gripper_link>
                <gripper_link>finger2_link</gripper_link>
            </arm>
            <forces_angle_tolerance>90</forces_angle_tolerance>
            <update_rate>4</update_rate>
            <grip_count_threshold>1</grip_count_threshold>
            <max_grip_count>2</max_grip_count>
            <release_tolerance>0.01</release_tolerance>
            <disable_collisions_on_attach>true</disable_collisions_on_attach>
            <contact_topic>__default_topic__</contact_topic>
        </plugin>
    </gazebo>
    <gazebo>
        <plugin filename="libroboticsgroup_upatras_gazebo_mimic_joint_plugin.so" name="finger2_link_mimic_joint_plugin">
            <joint>finger1_link</joint>
            <mimicJoint>finger2_link</mimicJoint>
            <multiplier>1.0</multiplier>
            <offset>0</offset>
            <sensitiveness>0.0</sensitiveness>
            <maxEffort>200</maxEffort>
        </plugin>
    </gazebo>
</robot>

